Workbook

Sheet Dirty_Retail_Data
A1: Order ID | B1: Order Date | C1: Ship Date | D1: Customer Name | E1: Segment | F1: Region | G1: State | H1: City | I1: Category | J1: Sub-Category | K1: Product Name | L1: Quantity | M1: Unit Price | N1: Discount | O1: Sales | P1: Profit | Q1: Ship Mode | R1: Payment Type
A2: ORD-1001 | B2: 2023-04-25 | C2: 2023-05-04 | D2: Meera Patel | E2: Home Office | F2: South | G2: California | H2: San Francisco | I2: Technology | J2: Accessories | K2: Keyboard | L2: 5 | M2: 116.24 | N2: 0.05 | O2: 552.14 | P2: 87.67 | Q2: Standard Class | R2: Card
A3: ORD-1002 | B3: 2023-08-27 | C3: 2023-09-05 | D3: Anaya Rao | E3: Consumer | F3: South | G3: Illinois | H3: Peoria | I3: Furniture | J3: Tables | K3: Side Table | L3: 1 | M3: 256.07 | N3: 0.3 | O3: 179.25 | P3: 21.32 | Q3: First Class | R3: Card
A4: ORD-1003 | B4: 2024-12-15 | C4: 2024-12-22 | D4: Meera Patel | E4: Corporate | F4: Central | G4: Florida | H4: Orlando | I4: Furniture | J4: Tables | K4: Side Table | L4: 5 | M4: 76.72 | N4: 0.1 | O4: 345.24 | P4: -45.91 | Q4: First Class | R4: Card
A5: ORD-1004 | B5: 2024-04-15 | C5: 2024-04-21 | D5: Sara Khan | E5: Home Office | F5: West | G5: Illinois | H5: Chicago | I5: Technology | J5: Accessories | K5: Keyboard | L5: 7 | M5: 42.83 | N5: 0.1 | O5: 269.83 | P5: 54.38 | Q5: Second Class | R5: Bank Transfer
A6: ORD-1005 | B6: 2023-08-27 | C6: 2023-09-02 | D6: Sara Khan | E6: Home Office | F6: Central | G6: California | H6: San Diego | I6: Furniture | J6: Chairs | K6: Visitor Chair | L6: 5 | M6: 208.41 | N6: 0.1 | O6: 937.85 | P6: -98.64 | Q6: Standard Class | R6: Cash
A7: ORD-1006 | B7: 2023-09-08 | C7: 2023-09-12 | D7: Dev Mehta | E7: Consumer | F7: East | G7: New York | H7: Buffalo | I7: Technology | J7: Phones | K7: Desk Phone | L7: 7 | M7: 127.32 | N7: 0.3 | O7: 623.87 | P7: 85.19 | Q7: First Class | R7: Digital Wallet
A8: ORD-1007 | B8: 2023-03-09 | C8: 2023-03-17 | D8: Kabir Joshi | E8: Corporate | F8: East | G8: New York | H8: Albany | I8: Office Supplies | J8: Binders | K8: Ring Binder | L8: 6 | M8: 101.98 | N8: 0.15 | O8: 520.1 | P8: 1.04 | Q8: First Class | R8: Digital Wallet
A9: ORD-1008 | B9: 2024-02-13 | C9: 2024-02-15 | E9: Home Office | F9: East | G9: Texas | H9: Houston | I9: Technology | J9: Phones | K9: Wireless Phone | L9: 3 | M9: 233.21 | N9: 0 | O9: 699.63 | P9: 117.3 | Q9: Same Day | R9: Card
A10: ORD-1009 | B10: 2024-01-26 | C10: 2024-01-28 | D10: Riya Desai | E10: Home Office | F10: Central | G10: Illinois | H10: Springfield | I10: Office Supplies | J10: Paper | K10: A4 Paper | L10: 5 | M10: 437.22 | N10: 0 | O10: 2186.1 | P10: 290.6 | Q10: First Class | R10: Digital Wallet
A11: ORD-1010 | B11: 2024-04-09 | C11: 2024-04-11 | D11: Riya Desai | E11: Home Office | F11: East | G11: California | H11: San Francisco | I11: Furniture | J11: Tables | K11: Office Table | L11: 5 | M11: 437.57 | N11: 0.05 | O11: 2078.46 | P11: 111.27 | Q11: First Class | R11: Cash
A12: ORD-1011 | B12: 2024-06-27 | C12: 2024-07-02 | D12: Sara Khan | E12: Consumer | F12: East | G12: California | H12: San Francisco | I12: Technology | J12: Phones | K12: Wireless Phone | L12: 6 | M12: 223.96 | N12: 0 | O12: 1343.76 | P12: 332.43 | Q12: Standard Class | R12: Card
A13: ORD-1012 | B13: 2024-05-12 | C13: 2024-05-15 | D13: Riya Desai | E13: Home Office | F13: South | G13: California | H13: San Francisco | I13: Technology | J13: Accessories | K13: Keyboard | L13: 3 | M13: 64.75 | N13: 0.15 | O13: 165.11 | P13: 42.19 | Q13: Second Class | R13: Bank Transfer
A14: ORD-1013 | B14: 2024-11-18 | C14: 2024-11-22 | D14: Meera Patel | E14: Corporate | F14: West | G14: Washington | H14: Spokane | I14: Office Supplies | J14: Paper | K14: Copy Paper | L14: 8 | M14: 405.63 | N14: 0.15 | O14: 2758.28 | P14: -342.96 | Q14: Second Class | R14: Cash
A15: ORD-1014 | B15: 2023-03-14 | C15: 2023-03-16 | D15: Sara Khan | E15: Corporate | F15: west | G15: Washington | H15: Tacoma | I15: Furniture | J15: Chairs | K15: Ergo Chair | L15: 1 | M15: 109.19 | N15: 0 | O15: 109.19 | P15: 23.52 | Q15: Second Class | R15: Digital Wallet
A16: ORD-1015 | B16: 2024-04-29 | C16: 2024-05-06 | D16: Ishaan Verma | E16: Home Office | F16: West | G16: Florida | H16: Miami | I16: Furniture | J16: Tables | K16: Side Table | L16: 2 | M16: 50.84 | N16: 0.15 | O16: 86.43 | P16: -1.47 | Q16: Standard Class | R16: Card
A17: ORD-1016 | B17: 2023-12-14 | C17: 2023-12-17 | D17: Riya Desai | E17: Corporate | F17: East | G17: California | H17: Los Angeles | I17: Office Supplies | J17: Paper | K17: A4 Paper | L17: 4 | M17: 92.07 | N17: 0.15 | O17: 313.04 | P17: -36.16 | Q17: Same Day | R17: Card
A18: ORD-1017 | B18: 2024-10-29 | C18: 2024-11-06 | D18: Ishaan Verma | E18: Consumer | F18: South | G18: Illinois | H18: Chicago | I18: Furniture | J18: Chairs | K18: Ergo Chair | L18: 2 | M18: 417.45 | N18: 0.05 | O18: 793.15 | P18: -82.09 | Q18: Second Class | R18: Digital Wallet
A19: ORD-1018 | B19: 2024-02-04 | C19: 2024-02-13 | D19: Ishaan Verma | E19: Consumer | F19: East | G19: Texas | H19: Dallas | I19: Furniture | J19: Chairs | K19: Office Chair | L19: 5 | M19: 194.97 | N19: 0.3 | O19: 682.39 | P19: 189.63 | Q19: Second Class | R19: Card
A20: ORD-1019 | B20: 2024-07-09 | C20: 2024-07-18 | D20: Kabir Joshi | E20: Consumer | F20: West | G20: California | H20: San Francisco | I20: Technology | J20: Phones | K20: Desk Phone | L20: N/A | M20: 33.27 | N20: 0.2 | O20: 159.7 | P20: 6.28 | Q20: Standard Class | R20: Card
A21: ORD-1020 | B21: 2023-08-29 | C21: 2023-09-05 | D21: Dev Mehta | E21: Corporate | F21: East | G21: Florida | H21: Miami | I21: Technology | J21: Accessories | K21: Webcam | L21: 4 | M21: 263.88 | N21: 0 | O21: 1055.52 | P21: 110.74 | Q21: First Class | R21: Cash
A22: ORD-1021 | B22: 2024-02-10 | C22: 2024-02-12 | D22: Meera Patel | E22: Home Office | F22: East | G22: New York | H22: Albany | I22: Office Supplies | J22: Binders | K22: File Binder | L22: 5 | M22: 210.09 | N22: 0 | O22: 1050.45 | P22: -184.58 | Q22: First Class | R22: Cash
A23: ORD-1022 | B23: 2023-03-12 | C23: 2023-03-21 | D23: Aarav Shah | E23: Home Office | F23: Central | G23: New York | H23: Buffalo | I23: Office Supplies | J23: Binders | K23: File Binder | L23: 5 | M23: 77.72 | N23: 0.2 | O23: 310.88 | P23: 44.65 | Q23: Standard Class | R23: Cash
A24: ORD-1023 | B24: 2023-04-29 | C24: 2023-05-05 | D24: Sara Khan | E24: Home Office | G24: California | H24: San Francisco | I24: Office Supplies | J24: Binders | K24: File Binder | L24: 3 | M24: 128.38 | N24: 0.2 | O24: 308.11 | P24: -25.61 | Q24: Same Day | R24: Bank Transfer
A25: ORD-1024 | B25: 2023-04-05 | C25: 2023-04-10 | D25: Kabir Joshi | E25: Home Office | F25: South | G25: Washington | H25: Spokane | I25: Furniture | J25: Chairs | K25: Visitor Chair | L25: 5 | M25: 27.49 | N25: 0.1 | O25: 123.7 | P25: 21.61 | Q25: Same Day | R25: Card
A26: ORD-1025 | B26: 2023-03-19 | C26: 2023-03-26 | D26: Kabir Joshi | E26: Consumer | F26: Central | G26: Washington | H26: Seattle | I26: Furniture | J26: Chairs | K26: Office Chair | L26: 1 | M26: 376.89 | N26: 0.2 | O26: 301.51 | P26: 22.36 | Q26: Standard Class | R26: Bank Transfer
A27: ORD-1026 | B27: 2024-11-29 | C27: 2024-12-06 | D27: Kabir Joshi | E27: Consumer | F27: East | G27: New York | H27: Albany | I27: Furniture | J27: Tables | K27: Office Table | L27: 2 | M27: 164.33 | N27: 0.2 | O27: 262.93 | P27: 59.61 | Q27: Same Day | R27: Card
A28: ORD-1027 | B28: 2023-12-07 | C28: 2023-12-08 | D28: Ishaan Verma | E28: Consumer | F28: East | G28: Florida | H28: Tampa | I28: Furniture | J28: Tables | K28: Conference Table | L28: 4 | M28: 125.93 | N28: 0.3 | O28: 352.6 | P28: -45.94 | Q28: First Class | R28: Bank Transfer
A29: ORD-1028 | B29: 2023-08-17 | C29: 2023-08-22 | D29: Dev Mehta | E29: Home Office | F29: South | G29: California | H29: San Francisco | I29: Furniture | J29: Tables | K29: Side Table | L29: 4 | M29: 184.12 | N29: 0.1 | O29: 662.83 | P29: 144.23 | Q29: First Class | R29: Card
A30: ORD-1029 | B30: 2023-09-25 | C30: 2023-10-01 | D30: Anaya Rao | E30: Home Office | F30: West | G30: New York | H30: Albany | I30: Furniture | J30: Chairs | K30: Office Chair | L30: 5 | M30: 24.91 | N30: 0.2 | O30: 99.64 | P30: 1.98 | Q30: Second Class | R30: Bank Transfer
A31: ORD-1030 | B31: 2024-12-26 | C31: 2025-01-01 | D31: Dev Mehta | E31: Home Office | F31: West | G31: Florida | H31: Miami | I31: Furniture | J31: Chairs | K31: Visitor Chair | L31: 4 | M31: unknown | N31: 0 | O31: 675.96 | P31: 173.37 | Q31: First Class | R31: Bank Transfer
A32: ORD-1031 | B32: 2024-02-23 | C32: 2024-03-01 | D32: Kabir Joshi | E32: Home Office | F32: Central | G32: Texas | H32: Dallas | I32: Technology | J32: Accessories | K32: Mouse | L32: 5 | M32: 253.05 | N32: 0.05 | O32: 1201.99 | P32: 16.11 | Q32: Standard Class | R32: Bank Transfer
A33: ORD-1032 | B33: 2023-08-04 | C33: 2023-08-13 | D33: Ishaan Verma | E33: Home Office | F33: East | G33: Florida | H33: Tampa | I33: Office Supplies | J33: Binders | K33: File Binder | L33: 6 | M33: 213.52 | N33: 0.15 | O33: 1088.95 | P33: 142.42 | Q33: Standard Class | R33: Bank Transfer
A34: ORD-1033 | B34: 2024-11-10 | C34: 2024-11-14 | D34: Sara Khan | E34: Consumer | F34: West | G34: Washington | H34: Tacoma | I34: Technology | J34: Phones | K34: Desk Phone | L34: 6 | M34: 49.28 | N34: 0.05 | O34: 280.9 | P34: 36.37 | Q34: Second Class | R34: Digital Wallet
A35: ORD-1034 | B35: 2023-03-16 | C35: 2023-03-20 | D35: Kabir Joshi | E35: Home Office | F35: West | G35: Florida | H35: Orlando | I35: Technology | J35: Phones | K35: Desk Phone | L35: 4 | M35: 325.51 | N35: 0.15 | O35: 1106.73 | P35: 52.47 | Q35: Same Day | R35: Cash
A36: ORD-1035 | B36: 2024-12-13 | C36: 2024-12-21 | D36: Dev Mehta | E36: Corporate | F36: South | G36: Illinois | H36: Springfield | I36: Furniture | J36: Tables | K36: Side Table | L36: 1 | M36: 254.37 | N36: 0 | O36: 254.37 | P36: 7.62 | Q36: Same Day | R36: Cash
A37: ORD-1036 | B37: 2024-05-01 | C37: 2024-05-10 | D37: Ishaan Verma | E37: Home Office | F37: East | G37: Florida | H37: Orlando | I37: Technology | J37: Accessories | K37: Mouse | L37: 4 | M37: 379.22 | N37: 0.1 | O37: 1365.19 | P37: 235.19 | Q37: Same Day | R37: Card
A38: ORD-1037 | B38: 2023-10-20 | C38: 2023-10-23 | D38: Sara Khan | E38: Corporate | F38: East | G38: New York | H38: Buffalo | I38: technology | J38: Accessories | K38: Webcam | L38: 6 | M38: 149.31 | N38: 0.2 | O38: 716.69 | P38: -102.44 | Q38: Second Class | R38: Card
A39: ORD-1038 | B39: 2024-02-22 | C39: 2024-02-29 | D39: Aarav Shah | E39: Home Office | F39: South | G39: Texas | H39: Austin | I39: Office Supplies | J39: Paper | K39: Notebook Paper | L39: 8 | M39: 191.77 | N39: 0.05 | O39: 1457.45 | P39: 296.05 | Q39: Standard Class | R39: Bank Transfer
A40: ORD-1039 | B40: 2024-02-04 | C40: 2024-02-05 | D40: Anaya Rao | E40: Corporate | F40: South | G40: Florida | H40: Tampa | I40: Office Supplies | J40: Binders | K40: File Binder | L40: 4 | M40: 223.8 | N40: 0.1 | O40: 805.68 | P40: 16.5 | Q40: Second Class | R40: Digital Wallet
...

Sheet Retailed_Data
A1: Order ID | B1: Order Date | C1: Ship Date | D1: Customer Name | E1: Segment | F1: Region | G1: Region_Cleaned | H1: State | I1: City | J1: Category | K1: Sub-Category | L1: Product Name | M1: Quantity | N1: Quantity_Cleaned | O1: Unit Price | P1: Discount | Q1: Sales | R1: Sales_cleaned | S1: Profit | T1: Ship Mode | U1: Payment Type
A2: ORD-1001 | B2: 45041 | C2: 2023-05-04 | D2: Meera Patel | E2: Home Office | F2: South | G2: =IF(TRIM(F2)="","",PROPER(TRIM(F2))) -> South | H2: California | I2: San Francisco | J2: Technology | K2: Accessories | L2: Keyboard | M2: 5 | N2: =IFERROR(IF(TRIM(M2)="","",IF(UPPER(TRIM(M2))="N/A","",IF(VALUE(M2)<0,"",VALUE(M2)))),"") -> 5 | O2: 116.24 | P2: 0.05 | Q2: 552.14 | R2: =IFERROR(IF(Q2<>"",Q2,IF(OR(M2="",O2="",P2=""),"",IF(OR(M2<=0,O2<=0,P2<0,P2>1),"",ROUND(M2*O2*(1-P2),2)))),"") -> 552.14 | S2: 87.67 | T2: Standard Class | U2: Card
A3: ORD-1002 | B3: 45165 | C3: 2023-09-05 | D3: Anaya Rao | E3: Consumer | F3: South | G3: =IF(TRIM(F3)="","",PROPER(TRIM(F3))) -> South | H3: Illinois | I3: Peoria | J3: Furniture | K3: Tables | L3: Side Table | M3: 1 | N3: =IFERROR(IF(TRIM(M3)="","",IF(UPPER(TRIM(M3))="N/A","",IF(VALUE(M3)<0,"",VALUE(M3)))),"") -> 1 | O3: 256.07 | P3: 0.3 | Q3: 179.25 | R3: =IFERROR(IF(Q3<>"",Q3,IF(OR(M3="",O3="",P3=""),"",IF(OR(M3<=0,O3<=0,P3<0,P3>1),"",ROUND(M3*O3*(1-P3),2)))),"") -> 179.25 | S3: 21.32 | T3: First Class | U3: Card
A4: ORD-1003 | B4: 45641 | C4: 2024-12-22 | D4: Meera Patel | E4: Corporate | F4: Central | G4: =IF(TRIM(F4)="","",PROPER(TRIM(F4))) -> Central | H4: Florida | I4: Orlando | J4: Furniture | K4: Tables | L4: Side Table | M4: 5 | N4: =IFERROR(IF(TRIM(M4)="","",IF(UPPER(TRIM(M4))="N/A","",IF(VALUE(M4)<0,"",VALUE(M4)))),"") -> 5 | O4: 76.72 | P4: 0.1 | Q4: 345.24 | R4: =IFERROR(IF(Q4<>"",Q4,IF(OR(M4="",O4="",P4=""),"",IF(OR(M4<=0,O4<=0,P4<0,P4>1),"",ROUND(M4*O4*(1-P4),2)))),"") -> 345.24 | S4: -45.91 | T4: First Class | U4: Card
A5: ORD-1004 | B5: 45397 | C5: 2024-04-21 | D5: Sara Khan | E5: Home Office | F5: West | G5: =IF(TRIM(F5)="","",PROPER(TRIM(F5))) -> West | H5: Illinois | I5: Chicago | J5: Technology | K5: Accessories | L5: Keyboard | M5: 7 | N5: =IFERROR(IF(TRIM(M5)="","",IF(UPPER(TRIM(M5))="N/A","",IF(VALUE(M5)<0,"",VALUE(M5)))),"") -> 7 | O5: 42.83 | P5: 0.1 | Q5: 269.83 | R5: =IFERROR(IF(Q5<>"",Q5,IF(OR(M5="",O5="",P5=""),"",IF(OR(M5<=0,O5<=0,P5<0,P5>1),"",ROUND(M5*O5*(1-P5),2)))),"") -> 269.83 | S5: 54.38 | T5: Second Class | U5: Bank Transfer
A6: ORD-1005 | B6: 45165 | C6: 2023-09-02 | D6: Sara Khan | E6: Home Office | F6: Central | G6: =IF(TRIM(F6)="","",PROPER(TRIM(F6))) -> Central | H6: California | I6: San Diego | J6: Furniture | K6: Chairs | L6: Visitor Chair | M6: 5 | N6: =IFERROR(IF(TRIM(M6)="","",IF(UPPER(TRIM(M6))="N/A","",IF(VALUE(M6)<0,"",VALUE(M6)))),"") -> 5 | O6: 208.41 | P6: 0.1 | Q6: 937.85 | R6: =IFERROR(IF(Q6<>"",Q6,IF(OR(M6="",O6="",P6=""),"",IF(OR(M6<=0,O6<=0,P6<0,P6>1),"",ROUND(M6*O6*(1-P6),2)))),"") -> 937.85 | S6: -98.64 | T6: Standard Class | U6: Cash
A7: ORD-1006 | B7: 45177 | C7: 2023-09-12 | D7: Dev Mehta | E7: Consumer | F7: East | G7: =IF(TRIM(F7)="","",PROPER(TRIM(F7))) -> East | H7: New York | I7: Buffalo | J7: Technology | K7: Phones | L7: Desk Phone | M7: 7 | N7: =IFERROR(IF(TRIM(M7)="","",IF(UPPER(TRIM(M7))="N/A","",IF(VALUE(M7)<0,"",VALUE(M7)))),"") -> 7 | O7: 127.32 | P7: 0.3 | Q7: 623.87 | R7: =IFERROR(IF(Q7<>"",Q7,IF(OR(M7="",O7="",P7=""),"",IF(OR(M7<=0,O7<=0,P7<0,P7>1),"",ROUND(M7*O7*(1-P7),2)))),"") -> 623.87 | S7: 85.19 | T7: First Class | U7: Digital Wallet
A8: ORD-1007 | B8: 44994 | C8: 2023-03-17 | D8: Kabir Joshi | E8: Corporate | F8: East | G8: =IF(TRIM(F8)="","",PROPER(TRIM(F8))) -> East | H8: New York | I8: Albany | J8: Office Supplies | K8: Binders | L8: Ring Binder | M8: 6 | N8: =IFERROR(IF(TRIM(M8)="","",IF(UPPER(TRIM(M8))="N/A","",IF(VALUE(M8)<0,"",VALUE(M8)))),"") -> 6 | O8: 101.98 | P8: 0.15 | Q8: 520.1 | R8: =IFERROR(IF(Q8<>"",Q8,IF(OR(M8="",O8="",P8=""),"",IF(OR(M8<=0,O8<=0,P8<0,P8>1),"",ROUND(M8*O8*(1-P8),2)))),"") -> 520.1 | S8: 1.04 | T8: First Class | U8: Digital Wallet
A9: ORD-1008 | B9: 45335 | C9: 2024-02-15 | E9: Home Office | F9: East | G9: =IF(TRIM(F9)="","",PROPER(TRIM(F9))) -> East | H9: Texas | I9: Houston | J9: Technology | K9: Phones | L9: Wireless Phone | M9: 3 | N9: =IFERROR(IF(TRIM(M9)="","",IF(UPPER(TRIM(M9))="N/A","",IF(VALUE(M9)<0,"",VALUE(M9)))),"") -> 3 | O9: 233.21 | P9: 0 | Q9: 699.63 | R9: =IFERROR(IF(Q9<>"",Q9,IF(OR(M9="",O9="",P9=""),"",IF(OR(M9<=0,O9<=0,P9<0,P9>1),"",ROUND(M9*O9*(1-P9),2)))),"") -> 699.63 | S9: 117.3 | T9: Same Day | U9: Card
A10: ORD-1009 | B10: 45317 | C10: 2024-01-28 | D10: Riya Desai | E10: Home Office | F10: Central | G10: =IF(TRIM(F10)="","",PROPER(TRIM(F10))) -> Central | H10: Illinois | I10: Springfield | J10: Office Supplies | K10: Paper | L10: A4 Paper | M10: 5 | N10: =IFERROR(IF(TRIM(M10)="","",IF(UPPER(TRIM(M10))="N/A","",IF(VALUE(M10)<0,"",VALUE(M10)))),"") -> 5 | O10: 437.22 | P10: 0 | Q10: 2186.1 | R10: =IFERROR(IF(Q10<>"",Q10,IF(OR(M10="",O10="",P10=""),"",IF(OR(M10<=0,O10<=0,P10<0,P10>1),"",ROUND(M10*O10*(1-P10),2)))),"") -> 2186.1 | S10: 290.6 | T10: First Class | U10: Digital Wallet
A11: ORD-1010 | B11: 45391 | C11: 2024-04-11 | D11: Riya Desai | E11: Home Office | F11: East | G11: =IF(TRIM(F11)="","",PROPER(TRIM(F11))) -> East | H11: California | I11: San Francisco | J11: Furniture | K11: Tables | L11: Office Table | M11: 5 | N11: =IFERROR(IF(TRIM(M11)="","",IF(UPPER(TRIM(M11))="N/A","",IF(VALUE(M11)<0,"",VALUE(M11)))),"") -> 5 | O11: 437.57 | P11: 0.05 | Q11: 2078.46 | R11: =IFERROR(IF(Q11<>"",Q11,IF(OR(M11="",O11="",P11=""),"",IF(OR(M11<=0,O11<=0,P11<0,P11>1),"",ROUND(M11*O11*(1-P11),2)))),"") -> 2078.46 | S11: 111.27 | T11: First Class | U11: Cash
A12: ORD-1011 | B12: 45470 | C12: 2024-07-02 | D12: Sara Khan | E12: Consumer | F12: East | G12: =IF(TRIM(F12)="","",PROPER(TRIM(F12))) -> East | H12: California | I12: San Francisco | J12: Technology | K12: Phones | L12: Wireless Phone | M12: 6 | N12: =IFERROR(IF(TRIM(M12)="","",IF(UPPER(TRIM(M12))="N/A","",IF(VALUE(M12)<0,"",VALUE(M12)))),"") -> 6 | O12: 223.96 | P12: 0 | Q12: 1343.76 | R12: =IFERROR(IF(Q12<>"",Q12,IF(OR(M12="",O12="",P12=""),"",IF(OR(M12<=0,O12<=0,P12<0,P12>1),"",ROUND(M12*O12*(1-P12),2)))),"") -> 1343.76 | S12: 332.43 | T12: Standard Class | U12: Card
A13: ORD-1012 | B13: 45424 | C13: 2024-05-15 | D13: Riya Desai | E13: Home Office | F13: South | G13: =IF(TRIM(F13)="","",PROPER(TRIM(F13))) -> South | H13: California | I13: San Francisco | J13: Technology | K13: Accessories | L13: Keyboard | M13: 3 | N13: =IFERROR(IF(TRIM(M13)="","",IF(UPPER(TRIM(M13))="N/A","",IF(VALUE(M13)<0,"",VALUE(M13)))),"") -> 3 | O13: 64.75 | P13: 0.15 | Q13: 165.11 | R13: =IFERROR(IF(Q13<>"",Q13,IF(OR(M13="",O13="",P13=""),"",IF(OR(M13<=0,O13<=0,P13<0,P13>1),"",ROUND(M13*O13*(1-P13),2)))),"") -> 165.11 | S13: 42.19 | T13: Second Class | U13: Bank Transfer
A14: ORD-1013 | B14: 45614 | C14: 2024-11-22 | D14: Meera Patel | E14: Corporate | F14: West | G14: =IF(TRIM(F14)="","",PROPER(TRIM(F14))) -> West | H14: Washington | I14: Spokane | J14: Office Supplies | K14: Paper | L14: Copy Paper | M14: 8 | N14: =IFERROR(IF(TRIM(M14)="","",IF(UPPER(TRIM(M14))="N/A","",IF(VALUE(M14)<0,"",VALUE(M14)))),"") -> 8 | O14: 405.63 | P14: 0.15 | Q14: 2758.28 | R14: =IFERROR(IF(Q14<>"",Q14,IF(OR(M14="",O14="",P14=""),"",IF(OR(M14<=0,O14<=0,P14<0,P14>1),"",ROUND(M14*O14*(1-P14),2)))),"") -> 2758.28 | S14: -342.96 | T14: Second Class | U14: Cash
A15: ORD-1014 | B15: 44999 | C15: 2023-03-16 | D15: Sara Khan | E15: Corporate | F15: West | G15: =IF(TRIM(F15)="","",PROPER(TRIM(F15))) -> West | H15: Washington | I15: Tacoma | J15: Furniture | K15: Chairs | L15: Ergo Chair | M15: 1 | N15: =IFERROR(IF(TRIM(M15)="","",IF(UPPER(TRIM(M15))="N/A","",IF(VALUE(M15)<0,"",VALUE(M15)))),"") -> 1 | O15: 109.19 | P15: 0 | Q15: 109.19 | R15: =IFERROR(IF(Q15<>"",Q15,IF(OR(M15="",O15="",P15=""),"",IF(OR(M15<=0,O15<=0,P15<0,P15>1),"",ROUND(M15*O15*(1-P15),2)))),"") -> 109.19 | S15: 23.52 | T15: Second Class | U15: Digital Wallet
A16: ORD-1015 | B16: 45411 | C16: 2024-05-06 | D16: Ishaan Verma | E16: Home Office | F16: West | G16: =IF(TRIM(F16)="","",PROPER(TRIM(F16))) -> West | H16: Florida | I16: Miami | J16: Furniture | K16: Tables | L16: Side Table | M16: 2 | N16: =IFERROR(IF(TRIM(M16)="","",IF(UPPER(TRIM(M16))="N/A","",IF(VALUE(M16)<0,"",VALUE(M16)))),"") -> 2 | O16: 50.84 | P16: 0.15 | Q16: 86.43 | R16: =IFERROR(IF(Q16<>"",Q16,IF(OR(M16="",O16="",P16=""),"",IF(OR(M16<=0,O16<=0,P16<0,P16>1),"",ROUND(M16*O16*(1-P16),2)))),"") -> 86.43 | S16: -1.47 | T16: Standard Class | U16: Card
A17: ORD-1016 | B17: 45274 | C17: 2023-12-17 | D17: Riya Desai | E17: Corporate | F17: East | G17: =IF(TRIM(F17)="","",PROPER(TRIM(F17))) -> East | H17: California | I17: Los Angeles | J17: Office Supplies | K17: Paper | L17: A4 Paper | M17: 4 | N17: =IFERROR(IF(TRIM(M17)="","",IF(UPPER(TRIM(M17))="N/A","",IF(VALUE(M17)<0,"",VALUE(M17)))),"") -> 4 | O17: 92.07 | P17: 0.15 | Q17: 313.04 | R17: =IFERROR(IF(Q17<>"",Q17,IF(OR(M17="",O17="",P17=""),"",IF(OR(M17<=0,O17<=0,P17<0,P17>1),"",ROUND(M17*O17*(1-P17),2)))),"") -> 313.04 | S17: -36.16 | T17: Same Day | U17: Card
A18: ORD-1017 | B18: 45594 | C18: 2024-11-06 | D18: Ishaan Verma | E18: Consumer | F18: South | G18: =IF(TRIM(F18)="","",PROPER(TRIM(F18))) -> South | H18: Illinois | I18: Chicago | J18: Furniture | K18: Chairs | L18: Ergo Chair | M18: 2 | N18: =IFERROR(IF(TRIM(M18)="","",IF(UPPER(TRIM(M18))="N/A","",IF(VALUE(M18)<0,"",VALUE(M18)))),"") -> 2 | O18: 417.45 | P18: 0.05 | Q18: 793.15 | R18: =IFERROR(IF(Q18<>"",Q18,IF(OR(M18="",O18="",P18=""),"",IF(OR(M18<=0,O18<=0,P18<0,P18>1),"",ROUND(M18*O18*(1-P18),2)))),"") -> 793.15 | S18: -82.09 | T18: Second Class | U18: Digital Wallet
A19: ORD-1018 | B19: 45326 | C19: 2024-02-13 | D19: Ishaan Verma | E19: Consumer | F19: East | G19: =IF(TRIM(F19)="","",PROPER(TRIM(F19))) -> East | H19: Texas | I19: Dallas | J19: Furniture | K19: Chairs | L19: Office Chair | M19: 5 | N19: =IFERROR(IF(TRIM(M19)="","",IF(UPPER(TRIM(M19))="N/A","",IF(VALUE(M19)<0,"",VALUE(M19)))),"") -> 5 | O19: 194.97 | P19: 0.3 | Q19: 682.39 | R19: =IFERROR(IF(Q19<>"",Q19,IF(OR(M19="",O19="",P19=""),"",IF(OR(M19<=0,O19<=0,P19<0,P19>1),"",ROUND(M19*O19*(1-P19),2)))),"") -> 682.39 | S19: 189.63 | T19: Second Class | U19: Card
A20: ORD-1019 | B20: 45482 | C20: 2024-07-18 | D20: Kabir Joshi | E20: Consumer | F20: West | G20: =IF(TRIM(F20)="","",PROPER(TRIM(F20))) -> West | H20: California | I20: San Francisco | J20: Technology | K20: Phones | L20: Desk Phone | N20: =IFERROR(IF(TRIM(M20)="","",IF(UPPER(TRIM(M20))="N/A","",IF(VALUE(M20)<0,"",VALUE(M20)))),"") | O20: 33.27 | P20: 0.2 | Q20: 159.7 | R20: =IFERROR(IF(Q20<>"",Q20,IF(OR(M20="",O20="",P20=""),"",IF(OR(M20<=0,O20<=0,P20<0,P20>1),"",ROUND(M20*O20*(1-P20),2)))),"") -> 159.7 | S20: 6.28 | T20: Standard Class | U20: Card
A21: ORD-1020 | B21: 45167 | C21: 2023-09-05 | D21: Dev Mehta | E21: Corporate | F21: East | G21: =IF(TRIM(F21)="","",PROPER(TRIM(F21))) -> East | H21: Florida | I21: Miami | J21: Technology | K21: Accessories | L21: Webcam | M21: 4 | N21: =IFERROR(IF(TRIM(M21)="","",IF(UPPER(TRIM(M21))="N/A","",IF(VALUE(M21)<0,"",VALUE(M21)))),"") -> 4 | O21: 263.88 | P21: 0 | Q21: 1055.52 | R21: =IFERROR(IF(Q21<>"",Q21,IF(OR(M21="",O21="",P21=""),"",IF(OR(M21<=0,O21<=0,P21<0,P21>1),"",ROUND(M21*O21*(1-P21),2)))),"") -> 1055.52 | S21: 110.74 | T21: First Class | U21: Cash
A22: ORD-1021 | B22: 45332 | C22: 2024-02-12 | D22: Meera Patel | E22: Home Office | F22: East | G22: =IF(TRIM(F22)="","",PROPER(TRIM(F22))) -> East | H22: New York | I22: Albany | J22: Office Supplies | K22: Binders | L22: File Binder | M22: 5 | N22: =IFERROR(IF(TRIM(M22)="","",IF(UPPER(TRIM(M22))="N/A","",IF(VALUE(M22)<0,"",VALUE(M22)))),"") -> 5 | O22: 210.09 | P22: 0 | Q22: 1050.45 | R22: =IFERROR(IF(Q22<>"",Q22,IF(OR(M22="",O22="",P22=""),"",IF(OR(M22<=0,O22<=0,P22<0,P22>1),"",ROUND(M22*O22*(1-P22),2)))),"") -> 1050.45 | S22: -184.58 | T22: First Class | U22: Cash
A23: ORD-1022 | B23: 44997 | C23: 2023-03-21 | D23: Aarav Shah | E23: Home Office | F23: Central | G23: =IF(TRIM(F23)="","",PROPER(TRIM(F23))) -> Central | H23: New York | I23: Buffalo | J23: Office Supplies | K23: Binders | L23: File Binder | M23: 5 | N23: =IFERROR(IF(TRIM(M23)="","",IF(UPPER(TRIM(M23))="N/A","",IF(VALUE(M23)<0,"",VALUE(M23)))),"") -> 5 | O23: 77.72 | P23: 0.2 | Q23: 310.88 | R23: =IFERROR(IF(Q23<>"",Q23,IF(OR(M23="",O23="",P23=""),"",IF(OR(M23<=0,O23<=0,P23<0,P23>1),"",ROUND(M23*O23*(1-P23),2)))),"") -> 310.88 | S23: 44.65 | T23: Standard Class | U23: Cash
A24: ORD-1023 | B24: 45045 | C24: 2023-05-05 | D24: Sara Khan | E24: Home Office | G24: Unknown | H24: California | I24: San Francisco | J24: Office Supplies | K24: Binders | L24: File Binder | M24: 3 | N24: =IFERROR(IF(TRIM(M24)="","",IF(UPPER(TRIM(M24))="N/A","",IF(VALUE(M24)<0,"",VALUE(M24)))),"") -> 3 | O24: 128.38 | P24: 0.2 | Q24: 308.11 | R24: =IFERROR(IF(Q24<>"",Q24,IF(OR(M24="",O24="",P24=""),"",IF(OR(M24<=0,O24<=0,P24<0,P24>1),"",ROUND(M24*O24*(1-P24),2)))),"") -> 308.11 | S24: -25.61 | T24: Same Day | U24: Bank Transfer
A25: ORD-1024 | B25: 45021 | C25: 2023-04-10 | D25: Kabir Joshi | E25: Home Office | F25: South | G25: =IF(TRIM(F25)="","",PROPER(TRIM(F25))) -> South | H25: Washington | I25: Spokane | J25: Furniture | K25: Chairs | L25: Visitor Chair | M25: 5 | N25: =IFERROR(IF(TRIM(M25)="","",IF(UPPER(TRIM(M25))="N/A","",IF(VALUE(M25)<0,"",VALUE(M25)))),"") -> 5 | O25: 27.49 | P25: 0.1 | Q25: 123.7 | R25: =IFERROR(IF(Q25<>"",Q25,IF(OR(M25="",O25="",P25=""),"",IF(OR(M25<=0,O25<=0,P25<0,P25>1),"",ROUND(M25*O25*(1-P25),2)))),"") -> 123.7 | S25: 21.61 | T25: Same Day | U25: Card
A26: ORD-1025 | B26: 45004 | C26: 2023-03-26 | D26: Kabir Joshi | E26: Consumer | F26: Central | G26: =IF(TRIM(F26)="","",PROPER(TRIM(F26))) -> Central | H26: Washington | I26: Seattle | J26: Furniture | K26: Chairs | L26: Office Chair | M26: 1 | N26: =IFERROR(IF(TRIM(M26)="","",IF(UPPER(TRIM(M26))="N/A","",IF(VALUE(M26)<0,"",VALUE(M26)))),"") -> 1 | O26: 376.89 | P26: 0.2 | Q26: 301.51 | R26: =IFERROR(IF(Q26<>"",Q26,IF(OR(M26="",O26="",P26=""),"",IF(OR(M26<=0,O26<=0,P26<0,P26>1),"",ROUND(M26*O26*(1-P26),2)))),"") -> 301.51 | S26: 22.36 | T26: Standard Class | U26: Bank Transfer
A27: ORD-1026 | B27: 45625 | C27: 2024-12-06 | D27: Kabir Joshi | E27: Consumer | F27: East | G27: =IF(TRIM(F27)="","",PROPER(TRIM(F27))) -> East | H27: New York | I27: Albany | J27: Furniture | K27: Tables | L27: Office Table | M27: 2 | N27: =IFERROR(IF(TRIM(M27)="","",IF(UPPER(TRIM(M27))="N/A","",IF(VALUE(M27)<0,"",VALUE(M27)))),"") -> 2 | O27: 164.33 | P27: 0.2 | Q27: 262.93 | R27: =IFERROR(IF(Q27<>"",Q27,IF(OR(M27="",O27="",P27=""),"",IF(OR(M27<=0,O27<=0,P27<0,P27>1),"",ROUND(M27*O27*(1-P27),2)))),"") -> 262.93 | S27: 59.61 | T27: Same Day | U27: Card
A28: ORD-1027 | B28: 45267 | C28: 2023-12-08 | D28: Ishaan Verma | E28: Consumer | F28: East | G28: =IF(TRIM(F28)="","",PROPER(TRIM(F28))) -> East | H28: Florida | I28: Tampa | J28: Furniture | K28: Tables | L28: Conference Table | M28: 4 | N28: =IFERROR(IF(TRIM(M28)="","",IF(UPPER(TRIM(M28))="N/A","",IF(VALUE(M28)<0,"",VALUE(M28)))),"") -> 4 | O28: 125.93 | P28: 0.3 | Q28: 352.6 | R28: =IFERROR(IF(Q28<>"",Q28,IF(OR(M28="",O28="",P28=""),"",IF(OR(M28<=0,O28<=0,P28<0,P28>1),"",ROUND(M28*O28*(1-P28),2)))),"") -> 352.6 | S28: -45.94 | T28: First Class | U28: Bank Transfer
A29: ORD-1028 | B29: 45155 | C29: 2023-08-22 | D29: Dev Mehta | E29: Home Office | F29: South | G29: =IF(TRIM(F29)="","",PROPER(TRIM(F29))) -> South | H29: California | I29: San Francisco | J29: Furniture | K29: Tables | L29: Side Table | M29: 4 | N29: =IFERROR(IF(TRIM(M29)="","",IF(UPPER(TRIM(M29))="N/A","",IF(VALUE(M29)<0,"",VALUE(M29)))),"") -> 4 | O29: 184.12 | P29: 0.1 | Q29: 662.83 | R29: =IFERROR(IF(Q29<>"",Q29,IF(OR(M29="",O29="",P29=""),"",IF(OR(M29<=0,O29<=0,P29<0,P29>1),"",ROUND(M29*O29*(1-P29),2)))),"") -> 662.83 | S29: 144.23 | T29: First Class | U29: Card
A30: ORD-1029 | B30: 45194 | C30: 2023-10-01 | D30: Anaya Rao | E30: Home Office | F30: West | G30: =IF(TRIM(F30)="","",PROPER(TRIM(F30))) -> West | H30: New York | I30: Albany | J30: Furniture | K30: Chairs | L30: Office Chair | M30: 5 | N30: =IFERROR(IF(TRIM(M30)="","",IF(UPPER(TRIM(M30))="N/A","",IF(VALUE(M30)<0,"",VALUE(M30)))),"") -> 5 | O30: 24.91 | P30: 0.2 | Q30: 99.64 | R30: =IFERROR(IF(Q30<>"",Q30,IF(OR(M30="",O30="",P30=""),"",IF(OR(M30<=0,O30<=0,P30<0,P30>1),"",ROUND(M30*O30*(1-P30),2)))),"") -> 99.64 | S30: 1.98 | T30: Second Class | U30: Bank Transfer
A31: ORD-1030 | B31: 45652 | C31: 2025-01-01 | D31: Dev Mehta | E31: Home Office | F31: West | G31: =IF(TRIM(F31)="","",PROPER(TRIM(F31))) -> West | H31: Florida | I31: Miami | J31: Furniture | K31: Chairs | L31: Visitor Chair | M31: 4 | N31: =IFERROR(IF(TRIM(M31)="","",IF(UPPER(TRIM(M31))="N/A","",IF(VALUE(M31)<0,"",VALUE(M31)))),"") -> 4 | P31: 0 | Q31: 675.96 | R31: =IFERROR(IF(Q31<>"",Q31,IF(OR(M31="",O31="",P31=""),"",IF(OR(M31<=0,O31<=0,P31<0,P31>1),"",ROUND(M31*O31*(1-P31),2)))),"") -> 675.96 | S31: 173.37 | T31: First Class | U31: Bank Transfer
A32: ORD-1031 | B32: 45345 | C32: 2024-03-01 | D32: Kabir Joshi | E32: Home Office | F32: Central | G32: =IF(TRIM(F32)="","",PROPER(TRIM(F32))) -> Central | H32: Texas | I32: Dallas | J32: Technology | K32: Accessories | L32: Mouse | M32: 5 | N32: =IFERROR(IF(TRIM(M32)="","",IF(UPPER(TRIM(M32))="N/A","",IF(VALUE(M32)<0,"",VALUE(M32)))),"") -> 5 | O32: 253.05 | P32: 0.05 | Q32: 1201.99 | R32: =IFERROR(IF(Q32<>"",Q32,IF(OR(M32="",O32="",P32=""),"",IF(OR(M32<=0,O32<=0,P32<0,P32>1),"",ROUND(M32*O32*(1-P32),2)))),"") -> 1201.99 | S32: 16.11 | T32: Standard Class | U32: Bank Transfer
A33: ORD-1032 | B33: 45142 | C33: 2023-08-13 | D33: Ishaan Verma | E33: Home Office | F33: East | G33: =IF(TRIM(F33)="","",PROPER(TRIM(F33))) -> East | H33: Florida | I33: Tampa | J33: Office Supplies | K33: Binders | L33: File Binder | M33: 6 | N33: =IFERROR(IF(TRIM(M33)="","",IF(UPPER(TRIM(M33))="N/A","",IF(VALUE(M33)<0,"",VALUE(M33)))),"") -> 6 | O33: 213.52 | P33: 0.15 | Q33: 1088.95 | R33: =IFERROR(IF(Q33<>"",Q33,IF(OR(M33="",O33="",P33=""),"",IF(OR(M33<=0,O33<=0,P33<0,P33>1),"",ROUND(M33*O33*(1-P33),2)))),"") -> 1088.95 | S33: 142.42 | T33: Standard Class | U33: Bank Transfer
A34: ORD-1033 | B34: 45606 | C34: 2024-11-14 | D34: Sara Khan | E34: Consumer | F34: West | G34: =IF(TRIM(F34)="","",PROPER(TRIM(F34))) -> West | H34: Washington | I34: Tacoma | J34: Technology | K34: Phones | L34: Desk Phone | M34: 6 | N34: =IFERROR(IF(TRIM(M34)="","",IF(UPPER(TRIM(M34))="N/A","",IF(VALUE(M34)<0,"",VALUE(M34)))),"") -> 6 | O34: 49.28 | P34: 0.05 | Q34: 280.9 | R34: =IFERROR(IF(Q34<>"",Q34,IF(OR(M34="",O34="",P34=""),"",IF(OR(M34<=0,O34<=0,P34<0,P34>1),"",ROUND(M34*O34*(1-P34),2)))),"") -> 280.9 | S34: 36.37 | T34: Second Class | U34: Digital Wallet
A35: ORD-1034 | B35: 45001 | C35: 2023-03-20 | D35: Kabir Joshi | E35: Home Office | F35: West | G35: =IF(TRIM(F35)="","",PROPER(TRIM(F35))) -> West | H35: Florida | I35: Orlando | J35: Technology | K35: Phones | L35: Desk Phone | M35: 4 | N35: =IFERROR(IF(TRIM(M35)="","",IF(UPPER(TRIM(M35))="N/A","",IF(VALUE(M35)<0,"",VALUE(M35)))),"") -> 4 | O35: 325.51 | P35: 0.15 | Q35: 1106.73 | R35: =IFERROR(IF(Q35<>"",Q35,IF(OR(M35="",O35="",P35=""),"",IF(OR(M35<=0,O35<=0,P35<0,P35>1),"",ROUND(M35*O35*(1-P35),2)))),"") -> 1106.73 | S35: 52.47 | T35: Same Day | U35: Cash
A36: ORD-1035 | B36: 45639 | C36: 2024-12-21 | D36: Dev Mehta | E36: Corporate | F36: South | G36: =IF(TRIM(F36)="","",PROPER(TRIM(F36))) -> South | H36: Illinois | I36: Springfield | J36: Furniture | K36: Tables | L36: Side Table | M36: 1 | N36: =IFERROR(IF(TRIM(M36)="","",IF(UPPER(TRIM(M36))="N/A","",IF(VALUE(M36)<0,"",VALUE(M36)))),"") -> 1 | O36: 254.37 | P36: 0 | Q36: 254.37 | R36: =IFERROR(IF(Q36<>"",Q36,IF(OR(M36="",O36="",P36=""),"",IF(OR(M36<=0,O36<=0,P36<0,P36>1),"",ROUND(M36*O36*(1-P36),2)))),"") -> 254.37 | S36: 7.62 | T36: Same Day | U36: Cash
A37: ORD-1036 | B37: 45413 | C37: 2024-05-10 | D37: Ishaan Verma | E37: Home Office | F37: East | G37: =IF(TRIM(F37)="","",PROPER(TRIM(F37))) -> East | H37: Florida | I37: Orlando | J37: Technology | K37: Accessories | L37: Mouse | M37: 4 | N37: =IFERROR(IF(TRIM(M37)="","",IF(UPPER(TRIM(M37))="N/A","",IF(VALUE(M37)<0,"",VALUE(M37)))),"") -> 4 | O37: 379.22 | P37: 0.1 | Q37: 1365.19 | R37: =IFERROR(IF(Q37<>"",Q37,IF(OR(M37="",O37="",P37=""),"",IF(OR(M37<=0,O37<=0,P37<0,P37>1),"",ROUND(M37*O37*(1-P37),2)))),"") -> 1365.19 | S37: 235.19 | T37: Same Day | U37: Card
A38: ORD-1037 | B38: 45219 | C38: 2023-10-23 | D38: Sara Khan | E38: Corporate | F38: East | G38: =IF(TRIM(F38)="","",PROPER(TRIM(F38))) -> East | H38: New York | I38: Buffalo | J38: Technology | K38: Accessories | L38: Webcam | M38: 6 | N38: =IFERROR(IF(TRIM(M38)="","",IF(UPPER(TRIM(M38))="N/A","",IF(VALUE(M38)<0,"",VALUE(M38)))),"") -> 6 | O38: 149.31 | P38: 0.2 | Q38: 716.69 | R38: =IFERROR(IF(Q38<>"",Q38,IF(OR(M38="",O38="",P38=""),"",IF(OR(M38<=0,O38<=0,P38<0,P38>1),"",ROUND(M38*O38*(1-P38),2)))),"") -> 716.69 | S38: -102.44 | T38: Second Class | U38: Card
A39: ORD-1038 | B39: 45344 | C39: 2024-02-29 | D39: Aarav Shah | E39: Home Office | F39: South | G39: =IF(TRIM(F39)="","",PROPER(TRIM(F39))) -> South | H39: Texas | I39: Austin | J39: Office Supplies | K39: Paper | L39: Notebook Paper | M39: 8 | N39: =IFERROR(IF(TRIM(M39)="","",IF(UPPER(TRIM(M39))="N/A","",IF(VALUE(M39)<0,"",VALUE(M39)))),"") -> 8 | O39: 191.77 | P39: 0.05 | Q39: 1457.45 | R39: =IFERROR(IF(Q39<>"",Q39,IF(OR(M39="",O39="",P39=""),"",IF(OR(M39<=0,O39<=0,P39<0,P39>1),"",ROUND(M39*O39*(1-P39),2)))),"") -> 1457.45 | S39: 296.05 | T39: Standard Class | U39: Bank Transfer
A40: ORD-1039 | B40: 45326 | C40: 2024-02-05 | D40: Anaya Rao | E40: Corporate | F40: South | G40: =IF(TRIM(F40)="","",PROPER(TRIM(F40))) -> South | H40: Florida | I40: Tampa | J40: Office Supplies | K40: Binders | L40: File Binder | M40: 4 | N40: =IFERROR(IF(TRIM(M40)="","",IF(UPPER(TRIM(M40))="N/A","",IF(VALUE(M40)<0,"",VALUE(M40)))),"") -> 4 | O40: 223.8 | P40: 0.1 | Q40: 805.68 | R40: =IFERROR(IF(Q40<>"",Q40,IF(OR(M40="",O40="",P40=""),"",IF(OR(M40<=0,O40<=0,P40<0,P40>1),"",ROUND(M40*O40*(1-P40),2)))),"") -> 805.68 | S40: 16.5 | T40: Second Class | U40: Digital Wallet
...

Sheet KPI
A1: Sales_Analysis
A3: KPI
A4: Total Sales | B4: =SUM(Dirty_Retail_Data!O2:O251) -> 213895.44
A5: Total Cleaned Sales | B5: =SUM(Retailed_Data!R2:R251) -> 214419.13
A6: Total Profit | B6: =SUM(Retailed_Data!S2:S251) -> 8261.65
A7: Profit Margin | B7: =IFERROR(B6/B5,0) -> 0.038530377
A8: Total Orders | B8: =COUNTA(Retailed_Data!A2:A251) -> 250
A9: Total Units Sold | B9: =SUM(Retailed_Data!M2:M251) -> 1148
A10: Total Cleaned Units Sold | B10: =SUM(Retailed_Data!N2:N251) -> 1151

Sheet Category_Analysis
A3: Row Labels | B3: Sum of Sales_cleaned | C3: Sum of Profit | D3: Profit Margin
A4: Furniture | B4: 56783.44 | C4: 2049.11 | D4: =IFERROR(C4/B4,0) -> 0.036086401
A5: Office Supplies | B5: 94587.46 | C5: 3935.36 | D5: =IFERROR(C5/B5,0) -> 0.041605515
A6: Technology | B6: 63048.23 | C6: 2277.18 | D6: =IFERROR(C6/B6,0) -> 0.036118064
A7: Grand Total | B7: 214419.13 | C7: 8261.65

Sheet Region_Analysis
A3: Row Labels | B3: Sum of Sales_cleaned | C3: Sum of Profit | D3: Profit_Margin
A4: Central | B4: 55778.1 | C4: 2624.5 | D4: =+IFERROR(C4/B4,0) -> 0.047052517
A5: East | B5: 57446.1 | C5: 1528.39 | D5: =+IFERROR(C5/B5,0) -> 0.026605636
A6: South | B6: 47670.7 | C6: 2448.85 | D6: =+IFERROR(C6/B6,0) -> 0.051370129
A7: West | B7: 53216.12 | C7: 1685.52 | D7: =+IFERROR(C7/B7,0) -> 0.03167311
A8: Unknown | B8: 308.11 | C8: -25.61 | D8: =+IFERROR(C8/B8,0) -> -0.083119665
A9: Grand Total | B9: 214419.13 | C9: 8261.65

Sheet Sales & Profit by Sub-Category
A3: Row Labels | B3: Sum of Sales_cleaned | C3: Sum of Profit
A4: Accessories | B4: 33351.86 | C4: 563.54
A5: Binders | B5: 48786.35 | C5: 2579
A6: Chairs | B6: 32358.68 | C6: 1807.22
A7: Paper | B7: 45801.11 | C7: 1356.36
A8: Phones | B8: 29696.37 | C8: 1713.64
A9: Tables | B9: 24424.76 | C9: 241.89
A10: Grand Total | B10: 214419.13 | C10: 8261.65

Sheet Discount_Analysis
A3: Row Labels | B3: Sum of Sales_cleaned | C3: Sum of Profit
A4: 0 | B4: 43273.45 | C4: 2012.99
A5: 0.05 | B5: 41684.7 | C5: 2017.76
A6: 0.1 | B6: 31252.51 | C6: 1652.98
A7: 0.15 | B7: 42533.4 | C7: 663.16
A8: 0.2 | B8: 29542.22 | C8: 635.2
A9: 0.3 | B9: 24419.72 | C9: 1471.8
A10: (blank) | B10: 1713.13 | C10: -192.24
A11: Grand Total | B11: 214419.13 | C11: 8261.65
